<?xml version="1.0" encoding="utf-8"?>
<!-- This URDF was automatically created by SolidWorks to URDF Exporter! Originally created by Stephen Brawner (brawner@gmail.com) 
     Commit Version: 1.6.0-4-g7f85cfe  Build Version: 1.6.7995.38578
     For more information, please see http://wiki.ros.org/sw_urdf_exporter -->
<robot
  name="control1">
  <link
    name="base_link">
    <inertial>
      <origin
        xyz="-0.0087008 0.0063258 -0.0099423"
        rpy="0 0 0" />
      <mass
        value="1.1805" />
      <inertia
        ixx="0.0016823"
        ixy="-2.7708E-06"
        ixz="-2.7829E-07"
        iyy="0.0014907"
        iyz="-2.1949E-06"
        izz="0.0029469" />
    </inertial>
    <visual>
      <origin
        xyz="0 0 0"
        rpy="0 0 0" />
      <geometry>
        <mesh
          filename="package://my_arm_description/meshes/base_link.STL" />
      </geometry>
      <material
        name="">
        <color
          rgba="0.22353 0.22353 0.22353 1" />
      </material>
    </visual>
    <collision>
      <origin
        xyz="0 0 0"
        rpy="0 0 0" />
      <geometry>
        <mesh
          filename="package://my_arm_description/meshes/base_link.STL" />
      </geometry>
    </collision>
  </link>
  <link
    name="link1">
    <inertial>
      <origin
        xyz="-0.00149373801870655 0.0337111398479079 -0.00975637542007314"
        rpy="0 0 0" />
      <mass
        value="0.246853952260659" />
      <inertia
        ixx="0.000125843242756008"
        ixy="1.74580538520557E-05"
        ixz="1.03609842670074E-06"
        iyy="0.000133860498909339"
        iyz="2.12254300849166E-06"
        izz="0.000115423860757801" />
    </inertial>
    <visual>
      <origin
        xyz="0 0 0"
        rpy="0 0 0" />
      <geometry>
        <mesh
          filename="package://my_arm_description/meshes/link1.STL" />
      </geometry>
      <material
        name="">
        <color
          rgba="0.372549019607843 0.372549019607843 0.372549019607843 1" />
      </material>
    </visual>
    <collision>
      <origin
        xyz="0 0 0"
        rpy="0 0 0" />
      <geometry>
        <mesh
          filename="package://my_arm_description/meshes/link1.STL" />
      </geometry>
    </collision>
  </link>
  <joint
    name="joint1"
    type="continuous">
    <origin
      xyz="0 -0.01 0.056"
      rpy="1.5708 0 3.1416" />
    <parent
      link="base_link" />
    <child
      link="link1" />
    <axis
      xyz="0 -1 0" />
    <limit
      lower="-3.14"
      upper="3.14"
      effort="100"
      velocity="1" />
  </joint>
  <link
    name="link2">
    <inertial>
      <origin
        xyz="0.064206 0.11105 -0.0088437"
        rpy="0 0 0" />
      <mass
        value="0.16728" />
      <inertia
        ixx="0.00020527"
        ixy="-9.6301E-05"
        ixz="-4.0546E-08"
        iyy="9.417E-05"
        iyz="-1.0314E-08"
        izz="0.00028085" />
    </inertial>
    <visual>
      <origin
        xyz="0 0 0"
        rpy="0 0 0" />
      <geometry>
        <mesh
          filename="package://my_arm_description/meshes/link2.STL" />
      </geometry>
      <material
        name="">
        <color
          rgba="1 1 1 1" />
      </material>
    </visual>
    <collision>
      <origin
        xyz="0 0 0"
        rpy="0 0 0" />
      <geometry>
        <mesh
          filename="package://my_arm_description/meshes/link2.STL" />
      </geometry>
    </collision>
  </link>
  <joint
    name="joint2"
    type="revolute">
    <origin
      xyz="0.0247 0.052 -0.0125"
      rpy="1.5708 0 1.5708" />
    <parent
      link="link1" />
    <child
      link="link2" />
    <axis
      xyz="0 0 -1" />
    <limit
      lower="-3.14"
      upper="3.14"
      effort="100"
      velocity="1" />
  </joint>
  <link
    name="link3">
    <inertial>
      <origin
        xyz="0.0396222970119211 0.0690947173240546 0.0107245369166011"
        rpy="0 0 0" />
      <mass
        value="0.0657688011125815" />
      <inertia
        ixx="0.000160574214329044"
        ixy="-8.81599534031968E-05"
        ixz="2.74036528467572E-08"
        iyy="6.16878954000704E-05"
        iyz="4.72976766113106E-08"
        izz="0.000221870194736637" />
    </inertial>
    <visual>
      <origin
        xyz="0 0 0"
        rpy="0 0 0" />
      <geometry>
        <mesh
          filename="package://my_arm_description/meshes/link3.STL" />
      </geometry>
      <material
        name="">
        <color
          rgba="1 1 1 1" />
      </material>
    </visual>
    <collision>
      <origin
        xyz="0 0 0"
        rpy="0 0 0" />
      <geometry>
        <mesh
          filename="package://my_arm_description/meshes/link3.STL" />
      </geometry>
    </collision>
  </link>
  <joint
    name="joint3"
    type="revolute">
    <origin
      xyz="0.08 0.13856 -0.041"
      rpy="3.1416 0 -0.70807" />
    <parent
      link="link2" />
    <child
      link="link3" />
    <axis
      xyz="0 0 -1" />
    <limit
      lower="-3.14"
      upper="3.14"
      effort="100"
      velocity="1" />
  </joint>
  <link
    name="link4">
    <inertial>
      <origin
        xyz="0.0248898704063124 -0.0238775624445878 -0.0110698247980451"
        rpy="0 0 0" />
      <mass
        value="0.0599680536065194" />
      <inertia
        ixx="2.67637089428356E-05"
        ixy="8.18755064407349E-06"
        ixz="3.97521147438038E-06"
        iyy="3.2708907549552E-05"
        iyz="-1.2678600766067E-06"
        izz="3.17076282551986E-05" />
    </inertial>
    <visual>
      <origin
        xyz="0 0 0"
        rpy="0 0 0" />
      <geometry>
        <mesh
          filename="package://my_arm_description/meshes/link4.STL" />
      </geometry>
      <material
        name="">
        <color
          rgba="1 1 1 1" />
      </material>
    </visual>
    <collision>
      <origin
        xyz="0 0 0"
        rpy="0 0 0" />
      <geometry>
        <mesh
          filename="package://my_arm_description/meshes/link4.STL" />
      </geometry>
    </collision>
  </link>
  <joint
    name="joint4"
    type="revolute">
    <origin
      xyz="0.08 0.13856 0.017"
      rpy="1.5708 0 -2.2789" />
    <parent
      link="link3" />
    <child
      link="link4" />
    <axis
      xyz="0 -1 0" />
    <limit
      lower="-3.14"
      upper="3.14"
      effort="100"
      velocity="1" />
  </joint>
  <link
    name="link5">
    <inertial>
      <origin
        xyz="0.0168639656312717 -0.0147907104348989 0.000231694525625326"
        rpy="0 0 0" />
      <mass
        value="0.0332241251365553" />
      <inertia
        ixx="3.65097165594158E-06"
        ixy="7.1426734922337E-07"
        ixz="2.05708542688781E-07"
        iyy="1.32713086327822E-05"
        iyz="-1.22668508060305E-07"
        izz="1.32410161776044E-05" />
    </inertial>
    <visual>
      <origin
        xyz="0 0 0"
        rpy="0 0 0" />
      <geometry>
        <mesh
          filename="package://my_arm_description/meshes/link5.STL" />
      </geometry>
      <material
        name="">
        <color
          rgba="1 1 1 1" />
      </material>
    </visual>
    <collision>
      <origin
        xyz="0 0 0"
        rpy="0 0 0" />
      <geometry>
        <mesh
          filename="package://my_arm_description/meshes/link5.STL" />
      </geometry>
    </collision>
  </link>
  <joint
    name="joint5"
    type="revolute">
    <origin
      xyz="-0.0418 -0.025 -0.015"
      rpy="0 0 0" />
    <parent
      link="link4" />
    <child
      link="link5" />
    <axis
      xyz="1 0 0" />
    <limit
      lower="-3.14"
      upper="3.14"
      effort="100"
      velocity="1" />
  </joint>
  <link
    name="link6">
    <inertial>
      <origin
        xyz="-0.0278266935177977 0.0123344794811341 0.0224125325758755"
        rpy="0 0 0" />
      <mass
        value="0.0349726138954135" />
      <inertia
        ixx="4.53103052878287E-06"
        ixy="4.13537754802921E-08"
        ixz="1.50493543795352E-06"
        iyy="6.04123328417643E-06"
        iyz="-4.41476357347198E-08"
        izz="5.19404904165638E-06" />
    </inertial>
    <visual>
      <origin
        xyz="0 0 0"
        rpy="0 0 0" />
      <geometry>
        <mesh
          filename="package://my_arm_description/meshes/link6.STL" />
      </geometry>
      <material
        name="">
        <color
          rgba="0.776470588235294 0.756862745098039 0.737254901960784 1" />
      </material>
    </visual>
    <collision>
      <origin
        xyz="0 0 0"
        rpy="0 0 0" />
      <geometry>
        <mesh
          filename="package://my_arm_description/meshes/link6.STL" />
      </geometry>
    </collision>
  </link>
  <joint
    name="joint6"
    type="revolute">
    <origin
      xyz="0 0.012 0"
      rpy="-3.1416 0.67749 0" />
    <parent
      link="link5" />
    <child
      link="link6" />
    <axis
      xyz="0 1 0" />
    <limit
      lower="-3.14"
      upper="3.14"
      effort="100"
      velocity="1" />
  </joint>
  <link
    name="link7">
    <inertial>
      <origin
        xyz="5.0062E-11 0.0035361 -2.6235E-09"
        rpy="0 0 0" />
      <mass
        value="0.0089679" />
      <inertia
        ixx="3.1268E-07"
        ixy="-6.0748E-15"
        ixz="2.2524E-13"
        iyy="4.0107E-07"
        iyz="-6.3682E-14"
        izz="3.1617E-07" />
    </inertial>
    <visual>
      <origin
        xyz="0 0 0"
        rpy="0 0 0" />
      <geometry>
        <mesh
          filename="package://my_arm_description/meshes/link7.STL" />
      </geometry>
      <material
        name="">
        <color
          rgba="0.77647 0.75686 0.73725 1" />
      </material>
    </visual>
    <collision>
      <origin
        xyz="0 0 0"
        rpy="0 0 0" />
      <geometry>
        <mesh
          filename="package://my_arm_description/meshes/link7.STL" />
      </geometry>
    </collision>
  </link>
  <joint
    name="joint7"
    type="continuous">
    <origin
      xyz="-0.06389 0.025 0.051401"
      rpy="-1.0147 -0.74064 -0.74432" />
    <parent
      link="link6" />
    <child
      link="link7" />
    <axis
      xyz="0 1 0" />
    <limit
      lower="-3.14"
      upper="3.14"
      effort="100"
      velocity="1" />
  </joint>
</robot>