<?xml version="1.0" encoding="utf-8"?>
<!-- This URDF was automatically created by SolidWorks to URDF Exporter! Originally created by Stephen Brawner (brawner@gmail.com) 
     Commit Version: 1.6.0-4-g7f85cfe  Build Version: 1.6.7995.38578
     For more information, please see http://wiki.ros.org/sw_urdf_exporter -->
<robot
  name="control1">
  <link
    name="base_link">
    <inertial>
      <origin
        xyz="-1.99274388679551E-05 -0.010909388260082 0.034221724153267"
        rpy="0 0 0" />
      <mass
        value="0.111516151376738" />
      <inertia
        ixx="9.67513961011775E-05"
        ixy="8.27720520457174E-08"
        ixz="-3.46673455150649E-08"
        iyy="0.000100526944802677"
        iyz="-1.58208029053105E-06"
        izz="0.00017790222461053" />
    </inertial>
    <visual>
      <origin
        xyz="0 0 0"
        rpy="0 0 0" />
      <geometry>
        <mesh
          filename="package://my_arm_description/meshes/base_link.STL" />
      </geometry>
      <material
        name="">
        <color
          rgba="1 1 1 1" />
      </material>
    </visual>
    <collision>
      <origin
        xyz="0 0 0"
        rpy="0 0 0" />
      <geometry>
        <mesh
          filename="package://my_arm_description/meshes/base_link.STL" />
      </geometry>
    </collision>
  </link>
  <link
    name="link1">
    <inertial>
      <origin
        xyz="0.00444819648257627 -0.00174221005036109 -0.0640805327506986"
        rpy="0 0 0" />
      <mass
        value="0.517175146455813" />
      <inertia
        ixx="0.000212573405928668"
        ixy="4.52054499751958E-06"
        ixz="-1.01532353320077E-05"
        iyy="0.000215391328883793"
        iyz="-1.43110410204879E-05"
        izz="0.000284824549783863" />
    </inertial>
    <visual>
      <origin
        xyz="0 0 0"
        rpy="0 0 0" />
      <geometry>
        <mesh
          filename="package://my_arm_description/meshes/link1.STL" />
      </geometry>
      <material
        name="">
        <color
          rgba="0.180392156862745 0.180392156862745 0.180392156862745 1" />
      </material>
    </visual>
    <collision>
      <origin
        xyz="0 0 0"
        rpy="0 0 0" />
      <geometry>
        <mesh
          filename="package://my_arm_description/meshes/link1.STL" />
      </geometry>
    </collision>
  </link>
  <joint
    name="joint1"
    type="revolute">
    <origin
      xyz="0 -0.01 0.12105"
      rpy="0 0 -1.0472" />
    <parent
      link="base_link" />
    <child
      link="link1" />
    <axis
      xyz="0 0 -1" />
    <limit
      lower="-3.14"
      upper="3.14"
      effort="0"
      velocity="0" />
  </joint>
  <link
    name="link2">
    <inertial>
      <origin
        xyz="0.128277880700168 -0.0138437353611224 7.70545767860009E-05"
        rpy="0 0 0" />
      <mass
        value="0.167276387211561" />
      <inertia
        ixx="3.85469235134975E-05"
        ixy="-2.92047331809108E-08"
        ixz="-4.10995998785801E-08"
        iyy="0.000280852696747895"
        iyz="-2.99570708981985E-08"
        izz="0.000260896378080021" />
    </inertial>
    <visual>
      <origin
        xyz="0 0 0"
        rpy="0 0 0" />
      <geometry>
        <mesh
          filename="package://my_arm_description/meshes/link2.STL" />
      </geometry>
      <material
        name="">
        <color
          rgba="1 1 1 1" />
      </material>
    </visual>
    <collision>
      <origin
        xyz="0 0 0"
        rpy="0 0 0" />
      <geometry>
        <mesh
          filename="package://my_arm_description/meshes/link2.STL" />
      </geometry>
    </collision>
  </link>
  <joint
    name="joint2"
    type="revolute">
    <origin
      xyz="-0.0040247 -0.031971 -0.013048"
      rpy="0 -0.5236 2.618" />
    <parent
      link="link1" />
    <child
      link="link2" />
    <axis
      xyz="0 -1 0" />
    <limit
      lower="0"
      upper="1.57"
      effort="0"
      velocity="0" />
  </joint>
  <link
    name="link3">
    <inertial>
      <origin
        xyz="0.0396222970119209 0.0690947173240546 0.0107245369166012"
        rpy="0 0 0" />
      <mass
        value="0.0657688011125815" />
      <inertia
        ixx="0.000160574214329044"
        ixy="-8.81599534031968E-05"
        ixz="2.74036528467569E-08"
        iyy="6.16878954000704E-05"
        iyz="4.72976766113109E-08"
        izz="0.000221870194736637" />
    </inertial>
    <visual>
      <origin
        xyz="0 0 0"
        rpy="0 0 0" />
      <geometry>
        <mesh
          filename="package://my_arm_description/meshes/link3.STL" />
      </geometry>
      <material
        name="">
        <color
          rgba="1 1 1 1" />
      </material>
    </visual>
    <collision>
      <origin
        xyz="0 0 0"
        rpy="0 0 0" />
      <geometry>
        <mesh
          filename="package://my_arm_description/meshes/link3.STL" />
      </geometry>
    </collision>
  </link>
  <joint
    name="joint3"
    type="revolute">
    <origin
      xyz="0.16 -0.046 0"
      rpy="-1.5708 -1.3863 3.1416" />
    <parent
      link="link2" />
    <child
      link="link3" />
    <axis
      xyz="0 0 -1" />
    <limit
      lower="0"
      upper="3.14"
      effort="0"
      velocity="0" />
  </joint>
  <link
    name="link4_coupler" />
  <joint
    name="joint4_from_joint2"
    type="revolute">
    <origin
      xyz="0.079999 0.13856 -0.021"
      rpy="0.70807 1.5708 0" />
    <parent
      link="link3" />
    <child
      link="link4_coupler" />
    <axis
      xyz="1 0 0" />
    <mimic
      joint="joint2"
      multiplier="1.0"
      offset="0.0" />
    <limit
      lower="-6.28318"
      upper="6.28318"
      effort="100"
      velocity="2" />
  </joint>
  <joint
    name="joint4_from_joint3"
    type="revolute">
    <origin
      xyz="0 0 0"
      rpy="0 0 0" />
    <parent
      link="link4_coupler" />
    <child
      link="link4" />
    <axis
      xyz="1 0 0" />
    <mimic
      joint="joint3"
      multiplier="-1.0"
      offset="0.0" />
    <limit
      lower="-6.28318"
      upper="6.28318"
      effort="100"
      velocity="2" />
  </joint>
  <link
    name="link4">
    <inertial>
      <origin
        xyz="-0.0141224375554112 -0.0248887370043849 0.0110707790254457"
        rpy="0 0 0" />
      <mass
        value="0.0599680536065182" />
      <inertia
        ixx="3.27089075495511E-05"
        ixy="8.18755064407349E-06"
        ixz="-1.26786007660678E-06"
        iyy="2.67637089428355E-05"
        iyz="3.9752114743801E-06"
        izz="3.17076282551975E-05" />
    </inertial>
    <visual>
      <origin
        xyz="0 0 0"
        rpy="0 0 0" />
      <geometry>
        <mesh
          filename="package://my_arm_description/meshes/link4.STL" />
      </geometry>
      <material
        name="">
        <color
          rgba="1 1 1 1" />
      </material>
    </visual>
    <collision>
      <origin
        xyz="0 0 0"
        rpy="0 0 0" />
      <geometry>
        <mesh
          filename="package://my_arm_description/meshes/link4.STL" />
      </geometry>
    </collision>
  </link>
  <link
    name="link5">
    <inertial>
      <origin
        xyz="0.0168639656312723 -0.00179071043489803 0.000231694525625437"
        rpy="0 0 0" />
      <mass
        value="0.0332241251365541" />
      <inertia
        ixx="3.65097165594172E-06"
        ixy="7.14267349223382E-07"
        ixz="2.05708542688784E-07"
        iyy="1.32713086327822E-05"
        iyz="-1.22668508060302E-07"
        izz="1.32410161776046E-05" />
    </inertial>
    <visual>
      <origin
        xyz="0 0 0"
        rpy="0 0 0" />
      <geometry>
        <mesh
          filename="package://my_arm_description/meshes/link5.STL" />
      </geometry>
      <material
        name="">
        <color
          rgba="1 1 1 1" />
      </material>
    </visual>
    <collision>
      <origin
        xyz="0 0 0"
        rpy="0 0 0" />
      <geometry>
        <mesh
          filename="package://my_arm_description/meshes/link5.STL" />
      </geometry>
    </collision>
  </link>
  <joint
    name="joint5"
    type="continuous">
    <origin
      xyz="0 0.041801 0.015001"
      rpy="3.1416 0 -1.5708" />
    <parent
      link="link4" />
    <child
      link="link5" />
    <axis
      xyz="1 0 0" />
    <limit
      lower="-3.14"
      upper="3.14"
      effort="0"
      velocity="0" />
  </joint>
  <link
    name="link6">
    <inertial>
      <origin
        xyz="-0.0278266935177969 0.0123344794811379 0.0224125325758741"
        rpy="0 0 0" />
      <mass
        value="0.0349726138954209" />
      <inertia
        ixx="4.53103052878315E-06"
        ixy="4.13537754805069E-08"
        ixz="1.5049354379533E-06"
        iyy="6.041233284177E-06"
        iyz="-4.41476357346042E-08"
        izz="5.19404904165699E-06" />
    </inertial>
    <visual>
      <origin
        xyz="0 0 0"
        rpy="0 0 0" />
      <geometry>
        <mesh
          filename="package://my_arm_description/meshes/link6.STL" />
      </geometry>
      <material
        name="">
        <color
          rgba="0.776470588235294 0.756862745098039 0.737254901960784 1" />
      </material>
    </visual>
    <collision>
      <origin
        xyz="0 0 0"
        rpy="0 0 0" />
      <geometry>
        <mesh
          filename="package://my_arm_description/meshes/link6.STL" />
      </geometry>
    </collision>
  </link>
  <joint
    name="joint6"
    type="revolute">
    <origin
      xyz="0 0.025 0"
      rpy="-3.1416 0.67749 0" />
    <parent
      link="link5" />
    <child
      link="link6" />
    <axis
      xyz="0 1 0" />
    <limit
      lower="-1.57"
      upper="1.57"
      effort="0"
      velocity="0" />
  </joint>
  <link
    name="link7">
    <inertial>
      <origin
        xyz="5.00622043819732E-11 0.00353607686776644 -2.62348281987457E-09"
        rpy="0 0 0" />
      <mass
        value="0.00896787232203793" />
      <inertia
        ixx="3.12675286229379E-07"
        ixy="-6.07476494257136E-15"
        ixz="2.25238790534559E-13"
        iyy="4.01070807985688E-07"
        iyz="-6.36822112998035E-14"
        izz="3.16171592931573E-07" />
    </inertial>
    <visual>
      <origin
        xyz="0 0 0"
        rpy="0 0 0" />
      <geometry>
        <mesh
          filename="package://my_arm_description/meshes/link7.STL" />
      </geometry>
      <material
        name="">
        <color
          rgba="0.776470588235294 0.756862745098039 0.737254901960784 1" />
      </material>
    </visual>
    <collision>
      <origin
        xyz="0 0 0"
        rpy="0 0 0" />
      <geometry>
        <mesh
          filename="package://my_arm_description/meshes/link7.STL" />
      </geometry>
    </collision>
  </link>
  <joint
    name="joint7"
    type="continuous">
    <origin
      xyz="-0.06389 0.025 0.051401"
      rpy="-1.0147 -0.74064 -0.74432" />
    <parent
      link="link6" />
    <child
      link="link7" />
    <axis
      xyz="0 1 0" />
    <limit
      lower="-3.14"
      upper="3.14"
      effort="0"
      velocity="0" />
  </joint>
</robot>